Workbook

Sheet CIP-Main data
A1: Sector | B1: Year | C1: Month | D1: Year with Month | E1: Cereals and products | F1: Meat and fish | G1: Egg | H1: Milk and products | I1: Oils and fats | J1: Fruits | K1: Vegetables | L1: Pulses and products | M1: Sugar and Confectionery | N1: Spices | O1: Non-alcoholic beverages | P1: Prepared meals, snacks, sweets etc. | Q1: Food and beverages | R1: Pan, tobacco and intoxicants | S1: Clothing | T1: Footwear | U1: Clothing and footwear | V1: Housing | W1: Housing Updated | X1: Fuel and light | Y1: Household goods and services | Z1: Health | AA1: Transport and communication | AB1: Recreation and amusement | AC1: Education | AD1: Personal care and effects | AE1: Miscellaneous | AF1: General index | AG1: Food category | AH1: Tobacco category | AI1: Clothing category | AJ1: Housing categpry | AK1: Health category | AL1: Transport category | AM1: Recreation & amusement cat | AN1: Education cat
A2: Rural | B2: 2013 | C2: January | D2: =CONCATENATE($B2," ",$C2) -> 2013 January | E2: 107.5 | F2: 106.3 | G2: 108.1 | H2: 104.9 | I2: 106.1 | J2: 103.9 | K2: 101.9 | L2: 106.1 | M2: 106.8 | N2: 103.1 | O2: 104.8 | P2: 106.7 | Q2: 105.5 | R2: 105.1 | S2: 106.5 | T2: 105.8 | U2: 106.4 | V2: NA | W2: 100.3 | X2: 105.5 | Y2: 104.8 | Z2: 104 | AA2: 103.3 | AB2: 103.4 | AC2: 103.8 | AD2: 104.7 | AE2: 104 | AF2: 105.1 | AG2: =E2+F2+G2+H2+I2+J2+K2+L2+M2+N2+O2+P2+Q2 -> 1371.7 | AH2: 105.1 | AI2: =S2+T2 -> 212.3 | AJ2: =W2+X2+Y2+AD2+AE2 -> 519.3 | AK2: 104 | AL2: 103.3 | AM2: 103.4 | AN2: 103.8
A3: Urban | B3: 2013 | C3: January | D3: 2013 January | E3: 110.5 | F3: 109.1 | G3: 113 | H3: 103.6 | I3: 103.4 | J3: 102.3 | K3: 102.9 | L3: 105.8 | M3: 105.1 | N3: 101.8 | O3: 105.1 | P3: 107.9 | Q3: 105.9 | R3: 105.2 | S3: 105.9 | T3: 105 | U3: 105.8 | V3: 100.3 | W3: 100.3 | X3: 105.4 | Y3: 104.8 | Z3: 104.1 | AA3: 103.2 | AB3: 102.9 | AC3: 103.5 | AD3: 104.3 | AE3: 103.7 | AF3: 104 | AG3: 1376.4 | AH3: 105.2 | AI3: 210.9 | AJ3: 518.5 | AK3: 104.1 | AL3: 103.2 | AM3: 102.9 | AN3: 103.5
A4: Rural+Urban | B4: 2013 | C4: January | D4: 2013 January | E4: 108.4 | F4: 107.3 | G4: 110 | H4: 104.4 | I4: 105.1 | J4: 103.2 | K4: 102.2 | L4: 106 | M4: 106.2 | N4: 102.7 | O4: 104.9 | P4: 107.3 | Q4: 105.6 | R4: 105.1 | S4: 106.3 | T4: 105.5 | U4: 106.2 | V4: 100.3 | W4: 100.3 | X4: 105.5 | Y4: 104.8 | Z4: 104 | AA4: 103.2 | AB4: 103.1 | AC4: 103.6 | AD4: 104.5 | AE4: 103.9 | AF4: 104.6 | AG4: 1373.3 | AH4: 105.1 | AI4: 211.8 | AJ4: 519 | AK4: 104 | AL4: 103.2 | AM4: 103.1 | AN4: 103.6
A5: Rural | B5: 2013 | C5: February | D5: 2013 February | E5: 109.2 | F5: 108.7 | G5: 110.2 | H5: 105.4 | I5: 106.7 | J5: 104 | K5: 102.4 | L5: 105.9 | M5: 105.7 | N5: 103.1 | O5: 105.1 | P5: 107.7 | Q5: 106.3 | R5: 105.6 | S5: 107.1 | T5: 106.3 | U5: 107 | V5: NA | W5: 100.4 | X5: 106.2 | Y5: 105.2 | Z5: 104.4 | AA5: 103.9 | AB5: 104 | AC5: 104.1 | AD5: 104.6 | AE5: 104.4 | AF5: 105.8 | AG5: 1380.4 | AH5: 105.6 | AI5: 213.4 | AJ5: 520.8 | AK5: 104.4 | AL5: 103.9 | AM5: 104 | AN5: 104.1
A6: Urban | B6: 2013 | C6: February | D6: 2013 February | E6: 112.9 | F6: 112.9 | G6: 116.9 | H6: 104 | I6: 103.5 | J6: 103.1 | K6: 104.9 | L6: 104.1 | M6: 103.8 | N6: 102.3 | O6: 106 | P6: 109 | Q6: 107.2 | R6: 106 | S6: 106.6 | T6: 105.5 | U6: 106.4 | V6: 100.4 | W6: 100.4 | X6: 105.7 | Y6: 105.2 | Z6: 104.7 | AA6: 104.4 | AB6: 103.3 | AC6: 103.7 | AD6: 104.3 | AE6: 104.3 | AF6: 104.7 | AG6: 1390.6 | AH6: 106 | AI6: 212.1 | AJ6: 519.9 | AK6: 104.7 | AL6: 104.4 | AM6: 103.3 | AN6: 103.7
A7: Rural+Urban | B7: 2013 | C7: February | D7: 2013 February | E7: 110.4 | F7: 110.2 | G7: 112.8 | H7: 104.9 | I7: 105.5 | J7: 103.6 | K7: 103.2 | L7: 105.3 | M7: 105.1 | N7: 102.8 | O7: 105.5 | P7: 108.3 | Q7: 106.6 | R7: 105.7 | S7: 106.9 | T7: 106 | U7: 106.8 | V7: 100.4 | W7: 100.4 | X7: 106 | Y7: 105.2 | Z7: 104.5 | AA7: 104.2 | AB7: 103.6 | AC7: 103.9 | AD7: 104.5 | AE7: 104.4 | AF7: 105.3 | AG7: 1384.2 | AH7: 105.7 | AI7: 212.9 | AJ7: 520.5 | AK7: 104.5 | AL7: 104.2 | AM7: 103.6 | AN7: 103.9
A8: Rural | B8: 2013 | C8: March | D8: 2013 March | E8: 110.2 | F8: 108.8 | G8: 109.9 | H8: 105.6 | I8: 106.2 | J8: 105.7 | K8: 101.4 | L8: 105.7 | M8: 105 | N8: 103.3 | O8: 105.6 | P8: 108.2 | Q8: 106.6 | R8: 106.5 | S8: 107.6 | T8: 106.8 | U8: 107.5 | V8: NA | W8: 100.4 | X8: 106.1 | Y8: 105.6 | Z8: 104.7 | AA8: 104.6 | AB8: 104 | AC8: 104.3 | AD8: 104.3 | AE8: 104.6 | AF8: 106 | AG8: 1382.2 | AH8: 106.5 | AI8: 214.4 | AJ8: 521 | AK8: 104.7 | AL8: 104.6 | AM8: 104 | AN8: 104.3
A9: Urban | B9: 2013 | C9: March | D9: 2013 March | E9: 113.9 | F9: 111.4 | G9: 113.2 | H9: 104.3 | I9: 102.7 | J9: 104.9 | K9: 103.8 | L9: 103.5 | M9: 102.6 | N9: 102.4 | O9: 107 | P9: 109.8 | Q9: 107.3 | R9: 106.8 | S9: 107.2 | T9: 106 | U9: 107 | V9: 100.4 | W9: 100.4 | X9: 106 | Y9: 105.7 | Z9: 105.2 | AA9: 105.5 | AB9: 103.5 | AC9: 103.8 | AD9: 104.2 | AE9: 104.9 | AF9: 105 | AG9: 1386.8 | AH9: 106.8 | AI9: 213.2 | AJ9: 521.2 | AK9: 105.2 | AL9: 105.5 | AM9: 103.5 | AN9: 103.8
A10: Rural+Urban | B10: 2013 | C10: March | D10: 2013 March | E10: 111.4 | F10: 109.7 | G10: 111.2 | H10: 105.1 | I10: 104.9 | J10: 105.3 | K10: 102.2 | L10: 105 | M10: 104.2 | N10: 103 | O10: 106.2 | P10: 108.9 | Q10: 106.9 | R10: 106.6 | S10: 107.4 | T10: 106.5 | U10: 107.3 | V10: 100.4 | W10: 100.4 | X10: 106.1 | Y10: 105.6 | Z10: 104.9 | AA10: 105.1 | AB10: 103.7 | AC10: 104 | AD10: 104.3 | AE10: 104.7 | AF10: 105.5 | AG10: 1384 | AH10: 106.6 | AI10: 213.9 | AJ10: 521.1 | AK10: 104.9 | AL10: 105.1 | AM10: 103.7 | AN10: 104
A11: Rural | B11: 2013 | C11: April | D11: 2013 April | E11: 110.2 | F11: 109.5 | G11: 106.9 | H11: 106.3 | I11: 105.7 | J11: 108.3 | K11: 103.4 | L11: 105.7 | M11: 104.2 | N11: 103.2 | O11: 106.5 | P11: 108.8 | Q11: 107.1 | R11: 107.1 | S11: 108.1 | T11: 107.4 | U11: 108 | V11: NA | W11: 100.5 | X11: 106.5 | Y11: 106.1 | Z11: 105.1 | AA11: 104.4 | AB11: 104.5 | AC11: 104.8 | AD11: 102.7 | AE11: 104.6 | AF11: 106.4 | AG11: 1385.8 | AH11: 107.1 | AI11: 215.5 | AJ11: 520.4 | AK11: 105.1 | AL11: 104.4 | AM11: 104.5 | AN11: 104.8
A12: Urban | B12: 2013 | C12: April | D12: 2013 April | E12: 114.6 | F12: 113.4 | G12: 106 | H12: 104.7 | I12: 102.1 | J12: 109.5 | K12: 109.7 | L12: 104.6 | M12: 102 | N12: 103.5 | O12: 108.2 | P12: 110.6 | Q12: 108.8 | R12: 108.5 | S12: 107.9 | T12: 106.4 | U12: 107.7 | V12: 100.5 | W12: 100.5 | X12: 106.4 | Y12: 106.5 | Z12: 105.7 | AA12: 105 | AB12: 104 | AC12: 105.2 | AD12: 103.2 | AE12: 105.1 | AF12: 105.7 | AG12: 1397.7 | AH12: 108.5 | AI12: 214.3 | AJ12: 521.7 | AK12: 105.7 | AL12: 105 | AM12: 104 | AN12: 105.2
A13: Rural+Urban | B13: 2013 | C13: April | D13: 2013 April | E13: 111.6 | F13: 110.9 | G13: 106.6 | H13: 105.7 | I13: 104.4 | J13: 108.9 | K13: 105.5 | L13: 105.3 | M13: 103.5 | N13: 103.3 | O13: 107.2 | P13: 109.6 | Q13: 107.7 | R13: 107.5 | S13: 108 | T13: 107 | U13: 107.9 | V13: 100.5 | W13: 100.5 | X13: 106.5 | Y13: 106.3 | Z13: 105.3 | AA13: 104.7 | AB13: 104.2 | AC13: 105 | AD13: 102.9 | AE13: 104.8 | AF13: 106.1 | AG13: 1390.2 | AH13: 107.5 | AI13: 215 | AJ13: 521 | AK13: 105.3 | AL13: 104.7 | AM13: 104.2 | AN13: 105
A14: Rural | B14: 2013 | C14: May | D14: 2013 May | E14: 110.9 | F14: 109.8 | G14: 105.9 | H14: 107.5 | I14: 105.3 | J14: 108.1 | K14: 107.3 | L14: 106.1 | M14: 103.7 | N14: 104 | O14: 107.4 | P14: 109.9 | Q14: 108.1 | R14: 108.1 | S14: 108.8 | T14: 107.9 | U14: 108.6 | V14: NA | W14: 100.5 | X14: 107.5 | Y14: 106.8 | Z14: 105.7 | AA14: 104.1 | AB14: 105 | AC14: 105.5 | AD14: 102.1 | AE14: 104.8 | AF14: 107.2 | AG14: 1394 | AH14: 108.1 | AI14: 216.7 | AJ14: 521.7 | AK14: 105.7 | AL14: 104.1 | AM14: 105 | AN14: 105.5
A15: Urban | B15: 2013 | C15: May | D15: 2013 May | E15: 115.4 | F15: 114.2 | G15: 102.7 | H15: 105.5 | I15: 101.5 | J15: 110.6 | K15: 123.7 | L15: 105.2 | M15: 101.9 | N15: 105 | O15: 109.1 | P15: 111.3 | Q15: 111.1 | R15: 109.8 | S15: 108.5 | T15: 106.7 | U15: 108.3 | V15: 100.5 | W15: 100.5 | X15: 107.2 | Y15: 107.1 | Z15: 106.2 | AA15: 103.9 | AB15: 104.6 | AC15: 105.7 | AD15: 102.6 | AE15: 104.9 | AF15: 106.6 | AG15: 1417.2 | AH15: 109.8 | AI15: 215.2 | AJ15: 522.3 | AK15: 106.2 | AL15: 103.9 | AM15: 104.6 | AN15: 105.7
A16: Rural+Urban | B16: 2013 | C16: May | D16: 2013 May | E16: 112.3 | F16: 111.3 | G16: 104.7 | H16: 106.8 | I16: 103.9 | J16: 109.3 | K16: 112.9 | L16: 105.8 | M16: 103.1 | N16: 104.3 | O16: 108.1 | P16: 110.5 | Q16: 109.2 | R16: 108.6 | S16: 108.7 | T16: 107.4 | U16: 108.5 | V16: 100.5 | W16: 100.5 | X16: 107.4 | Y16: 106.9 | Z16: 105.9 | AA16: 104 | AB16: 104.8 | AC16: 105.6 | AD16: 102.3 | AE16: 104.8 | AF16: 106.9 | AG16: 1402.2 | AH16: 108.6 | AI16: 216.1 | AJ16: 521.9 | AK16: 105.9 | AL16: 104 | AM16: 104.8 | AN16: 105.6
A17: Rural | B17: 2013 | C17: June | D17: 2013 June | E17: 112.3 | F17: 112.1 | G17: 108.1 | H17: 108.3 | I17: 105.9 | J17: 109.2 | K17: 118 | L17: 106.8 | M17: 104.1 | N17: 105.4 | O17: 108.2 | P17: 111 | Q17: 110.6 | R17: 109 | S17: 109.7 | T17: 108.8 | U17: 109.5 | V17: NA | W17: 106.6 | X17: 108.5 | Y17: 107.5 | Z17: 106.3 | AA17: 105 | AB17: 105.6 | AC17: 106.5 | AD17: 102.5 | AE17: 105.5 | AF17: 108.9 | AG17: 1420 | AH17: 109 | AI17: 218.5 | AJ17: 530.6 | AK17: 106.3 | AL17: 105 | AM17: 105.6 | AN17: 106.5
A18: Urban | B18: 2013 | C18: June | D18: 2013 June | E18: 117 | F18: 120.1 | G18: 112.5 | H18: 107.3 | I18: 101.3 | J18: 112.4 | K18: 143.6 | L18: 105.4 | M18: 101.4 | N18: 106.4 | O18: 110 | P18: 112.2 | Q18: 115 | R18: 110.9 | S18: 109.2 | T18: 107.2 | U18: 108.9 | V18: 106.6 | W18: 106.6 | X18: 108 | Y18: 107.7 | Z18: 106.5 | AA18: 105.2 | AB18: 105.2 | AC18: 108.1 | AD18: 103.3 | AE18: 106.1 | AF18: 109.7 | AG18: 1464.6 | AH18: 110.9 | AI18: 216.4 | AJ18: 531.7 | AK18: 106.5 | AL18: 105.2 | AM18: 105.2 | AN18: 108.1
A19: Rural+Urban | B19: 2013 | C19: June | D19: 2013 June | E19: 113.8 | F19: 114.9 | G19: 109.8 | H19: 107.9 | I19: 104.2 | J19: 110.7 | K19: 126.7 | L19: 106.3 | M19: 103.2 | N19: 105.7 | O19: 109 | P19: 111.6 | Q19: 112.2 | R19: 109.5 | S19: 109.5 | T19: 108.1 | U19: 109.3 | V19: 106.6 | W19: 106.6 | X19: 108.3 | Y19: 107.6 | Z19: 106.4 | AA19: 105.1 | AB19: 105.4 | AC19: 107.4 | AD19: 102.8 | AE19: 105.8 | AF19: 109.3 | AG19: 1436 | AH19: 109.5 | AI19: 217.6 | AJ19: 531.1 | AK19: 106.4 | AL19: 105.1 | AM19: 105.4 | AN19: 107.4
A20: Rural | B20: 2013 | C20: July | D20: 2013 July | E20: 113.4 | F20: 114.9 | G20: 110.5 | H20: 109.3 | I20: 106.2 | J20: 110.3 | K20: 129.2 | L20: 107.1 | M20: 104.3 | N20: 106.4 | O20: 109.1 | P20: 112.1 | Q20: 113.1 | R20: 109.8 | S20: 110.5 | T20: 109.5 | U20: 110.3 | V20: NA | W20: 107.7 | X20: 109.5 | Y20: 108.3 | Z20: 106.9 | AA20: 106.8 | AB20: 106.4 | AC20: 107.8 | AD20: 102.5 | AE20: 106.5 | AF20: 110.7 | AG20: 1445.9 | AH20: 109.8 | AI20: 220 | AJ20: 534.5 | AK20: 106.9 | AL20: 106.8 | AM20: 106.4 | AN20: 107.8
A21: Urban | B21: 2013 | C21: July | D21: 2013 July | E21: 117.8 | F21: 119.2 | G21: 114 | H21: 108.3 | I21: 101.1 | J21: 113.2 | K21: 160.9 | L21: 105.1 | M21: 101.3 | N21: 107.5 | O21: 110.4 | P21: 113.1 | Q21: 117.5 | R21: 111.7 | S21: 109.8 | T21: 107.8 | U21: 109.5 | V21: 107.7 | W21: 107.7 | X21: 108.6 | Y21: 108.1 | Z21: 107.1 | AA21: 107.3 | AB21: 105.9 | AC21: 110.1 | AD21: 103.2 | AE21: 107.3 | AF21: 111.4 | AG21: 1489.4 | AH21: 111.7 | AI21: 217.6 | AJ21: 534.9 | AK21: 107.1 | AL21: 107.3 | AM21: 105.9 | AN21: 110.1
A22: Rural+Urban | B22: 2013 | C22: July | D22: 2013 July | E22: 114.8 | F22: 116.4 | G22: 111.9 | H22: 108.9 | I22: 104.3 | J22: 111.7 | K22: 140 | L22: 106.4 | M22: 103.3 | N22: 106.8 | O22: 109.6 | P22: 112.6 | Q22: 114.7 | R22: 110.3 | S22: 110.2 | T22: 108.8 | U22: 110 | V22: 107.7 | W22: 107.7 | X22: 109.2 | Y22: 108.2 | Z22: 107 | AA22: 107.1 | AB22: 106.1 | AC22: 109.1 | AD22: 102.8 | AE22: 106.9 | AF22: 111 | AG22: 1461.4 | AH22: 110.3 | AI22: 219 | AJ22: 534.8 | AK22: 107 | AL22: 107.1 | AM22: 106.1 | AN22: 109.1
A23: Rural | B23: 2013 | C23: August | D23: 2013 August | E23: 114.3 | F23: 115.4 | G23: 111.1 | H23: 110 | I23: 106.4 | J23: 110.8 | K23: 138.9 | L23: 107.4 | M23: 104.1 | N23: 106.9 | O23: 109.7 | P23: 112.6 | Q23: 114.9 | R23: 110.7 | S23: 111.3 | T23: 110.2 | U23: 111.1 | V23: NA | W23: 108.9 | X23: 109.9 | Y23: 108.7 | Z23: 107.5 | AA23: 107.8 | AB23: 106.8 | AC23: 108.7 | AD23: 105 | AE23: 107.5 | AF23: 112.1 | AG23: 1462.5 | AH23: 110.7 | AI23: 221.5 | AJ23: 540 | AK23: 107.5 | AL23: 107.8 | AM23: 106.8 | AN23: 108.7
A24: Urban | B24: 2013 | C24: August | D24: 2013 August | E24: 118.3 | F24: 120.4 | G24: 112.7 | H24: 108.9 | I24: 101.1 | J24: 108.7 | K24: 177 | L24: 104.7 | M24: 101 | N24: 108.5 | O24: 110.9 | P24: 114.3 | Q24: 119.6 | R24: 112.4 | S24: 110.6 | T24: 108.3 | U24: 110.2 | V24: 108.9 | W24: 108.9 | X24: 109.3 | Y24: 108.7 | Z24: 107.6 | AA24: 108.1 | AB24: 106.5 | AC24: 110.8 | AD24: 106 | AE24: 108.3 | AF24: 112.7 | AG24: 1506.1 | AH24: 112.4 | AI24: 218.9 | AJ24: 541.2 | AK24: 107.6 | AL24: 108.1 | AM24: 106.5 | AN24: 110.8
A25: Rural+Urban | B25: 2013 | C25: August | D25: 2013 August | E25: 115.6 | F25: 117.2 | G25: 111.7 | H25: 109.6 | I25: 104.5 | J25: 109.8 | K25: 151.8 | L25: 106.5 | M25: 103.1 | N25: 107.4 | O25: 110.2 | P25: 113.4 | Q25: 116.6 | R25: 111.2 | S25: 111 | T25: 109.4 | U25: 110.7 | V25: 108.9 | W25: 108.9 | X25: 109.7 | Y25: 108.7 | Z25: 107.5 | AA25: 108 | AB25: 106.6 | AC25: 109.9 | AD25: 105.4 | AE25: 107.9 | AF25: 112.4 | AG25: 1477.4 | AH25: 111.2 | AI25: 220.4 | AJ25: 540.6 | AK25: 107.5 | AL25: 108 | AM25: 106.6 | AN25: 109.9
A26: Rural | B26: 2013 | C26: September | D26: 2013 September | E26: 115.4 | F26: 115.7 | G26: 111.7 | H26: 111 | I26: 107.4 | J26: 110.9 | K26: 154 | L26: 108.1 | M26: 104.2 | N26: 107.9 | O26: 110.4 | P26: 114 | Q26: 117.8 | R26: 111.7 | S26: 112.7 | T26: 111.4 | U26: 112.5 | V26: NA | W26: 109.7 | X26: 111.1 | Y26: 109.6 | Z26: 108.3 | AA26: 109.3 | AB26: 107.7 | AC26: 109.8 | AD26: 106.7 | AE26: 108.7 | AF26: 114.2 | AG26: 1488.5 | AH26: 111.7 | AI26: 224.1 | AJ26: 545.8 | AK26: 108.3 | AL26: 109.3 | AM26: 107.7 | AN26: 109.8
A27: Urban | B27: 2013 | C27: September | D27: 2013 September | E27: 118.6 | F27: 119.1 | G27: 113.2 | H27: 109.6 | I27: 101.7 | J27: 103.2 | K27: 174.3 | L27: 105.1 | M27: 100.8 | N27: 109.1 | O27: 111.1 | P27: 115.4 | Q27: 119.2 | R27: 112.9 | S27: 111.4 | T27: 109 | U27: 111.1 | V27: 109.7 | W27: 109.7 | X27: 109.5 | Y27: 109.6 | Z27: 107.9 | AA27: 110.4 | AB27: 107.4 | AC27: 111.2 | AD27: 106.9 | AE27: 109.4 | AF27: 113.2 | AG27: 1500.4 | AH27: 112.9 | AI27: 220.4 | AJ27: 545.1 | AK27: 107.9 | AL27: 110.4 | AM27: 107.4 | AN27: 111.2
A28: Rural+Urban | B28: 2013 | C28: September | D28: 2013 September | E28: 116.4 | F28: 116.9 | G28: 112.3 | H28: 110.5 | I28: 105.3 | J28: 107.3 | K28: 160.9 | L28: 107.1 | M28: 103.1 | N28: 108.3 | O28: 110.7 | P28: 114.6 | Q28: 118.3 | R28: 112 | S28: 112.2 | T28: 110.4 | U28: 111.9 | V28: 109.7 | W28: 109.7 | X28: 110.5 | Y28: 109.6 | Z28: 108.1 | AA28: 109.9 | AB28: 107.5 | AC28: 110.6 | AD28: 106.8 | AE28: 109 | AF28: 113.7 | AG28: 1491.7 | AH28: 112 | AI28: 222.6 | AJ28: 545.6 | AK28: 108.1 | AL28: 109.9 | AM28: 107.5 | AN28: 110.6
A29: Rural | B29: 2013 | C29: October | D29: 2013 October | E29: 116.3 | F29: 115.4 | G29: 112.6 | H29: 111.7 | I29: 107.7 | J29: 113.2 | K29: 164.9 | L29: 108.3 | M29: 103.9 | N29: 108.2 | O29: 111.1 | P29: 114.9 | Q29: 119.8 | R29: 112.2 | S29: 113.6 | T29: 112.3 | U29: 113.4 | V29: NA | W29: 110.5 | X29: 111.6 | Y29: 110.4 | Z29: 108.9 | AA29: 109.3 | AB29: 108.3 | AC29: 110.2 | AD29: 107.5 | AE29: 109.1 | AF29: 115.5 | AG29: 1508 | AH29: 112.2 | AI29: 225.9 | AJ29: 549.1 | AK29: 108.9 | AL29: 109.3 | AM29: 108.3 | AN29: 110.2
A30: Urban | B30: 2013 | C30: October | D30: 2013 October | E30: 118.9 | F30: 118.1 | G30: 114.5 | H30: 110.4 | I30: 102.3 | J30: 106.2 | K30: 183.5 | L30: 105.3 | M30: 100.2 | N30: 109.6 | O30: 111.4 | P30: 116 | Q30: 120.8 | R30: 113.5 | S30: 112.5 | T30: 109.7 | U30: 112 | V30: 110.5 | W30: 110.5 | X30: 109.7 | Y30: 110.2 | Z30: 108.2 | AA30: 109.7 | AB30: 108 | AC30: 111.3 | AD30: 107.3 | AE30: 109.4 | AF30: 114 | AG30: 1517.2 | AH30: 113.5 | AI30: 222.2 | AJ30: 547.1 | AK30: 108.2 | AL30: 109.7 | AM30: 108 | AN30: 111.3
A31: Rural+Urban | B31: 2013 | C31: October | D31: 2013 October | E31: 117.1 | F31: 116.3 | G31: 113.3 | H31: 111.2 | I31: 105.7 | J31: 109.9 | K31: 171.2 | L31: 107.3 | M31: 102.7 | N31: 108.7 | O31: 111.2 | P31: 115.4 | Q31: 120.2 | R31: 112.5 | S31: 113.2 | T31: 111.2 | U31: 112.8 | V31: 110.5 | W31: 110.5 | X31: 110.9 | Y31: 110.3 | Z31: 108.6 | AA31: 109.5 | AB31: 108.1 | AC31: 110.8 | AD31: 107.4 | AE31: 109.2 | AF31: 114.8 | AG31: 1510.2 | AH31: 112.5 | AI31: 224.4 | AJ31: 548.3 | AK31: 108.6 | AL31: 109.5 | AM31: 108.1 | AN31: 110.8
A32: Rural | B32: 2013 | C32: November | D32: 2013 November | E32: 117.3 | F32: 114.9 | G32: 116.2 | H32: 112.8 | I32: 108.9 | J32: 116.6 | K32: 178.1 | L32: 109.1 | M32: 103.6 | N32: 109 | O32: 111.8 | P32: 116 | Q32: 122.5 | R32: 112.8 | S32: 114.6 | T32: 113.1 | U32: 114.4 | V32: NA | W32: 111.1 | X32: 112.6 | Y32: 111.3 | Z32: 109.7 | AA32: 109.6 | AB32: 108.7 | AC32: 111 | AD32: 108.2 | AE32: 109.8 | AF32: 117.4 | AG32: 1536.8 | AH32: 112.8 | AI32: 227.7 | AJ32: 553 | AK32: 109.7 | AL32: 109.6 | AM32: 108.7 | AN32: 111
A33: Urban | B33: 2013 | C33: November | D33: 2013 November | E33: 119.8 | F33: 116.3 | G33: 122.6 | H33: 112 | I33: 103.2 | J33: 110 | K33: 192.8 | L33: 106.3 | M33: 99.5 | N33: 110.3 | O33: 111.8 | P33: 117.1 | Q33: 122.9 | R33: 114.1 | S33: 113.5 | T33: 110.3 | U33: 113 | V33: 111.1 | W33: 111.1 | X33: 110 | Y33: 110.9 | Z33: 108.6 | AA33: 109.5 | AB33: 108.5 | AC33: 111.3 | AD33: 107.9 | AE33: 109.6 | AF33: 115 | AG33: 1544.6 | AH33: 114.1 | AI33: 223.8 | AJ33: 549.5 | AK33: 108.6 | AL33: 109.5 | AM33: 108.5 | AN33: 111.3
A34: Rural+Urban | B34: 2013 | C34: November | D34: 2013 November | E34: 118.1 | F34: 115.4 | G34: 118.7 | H34: 112.5 | I34: 106.8 | J34: 113.5 | K34: 183.1 | L34: 108.2 | M34: 102.2 | N34: 109.4 | O34: 111.8 | P34: 116.5 | Q34: 122.6 | R34: 113.1 | S34: 114.2 | T34: 111.9 | U34: 113.8 | V34: 111.1 | W34: 111.1 | X34: 111.6 | Y34: 111.1 | Z34: 109.3 | AA34: 109.5 | AB34: 108.6 | AC34: 111.2 | AD34: 108.1 | AE34: 109.7 | AF34: 116.3 | AG34: 1538.8 | AH34: 113.1 | AI34: 226.1 | AJ34: 551.6 | AK34: 109.3 | AL34: 109.5 | AM34: 108.6 | AN34: 111.2
A35: Rural | B35: 2013 | C35: December | D35: 2013 December | E35: 118.4 | F35: 115.9 | G35: 120.4 | H35: 113.8 | I35: 109.5 | J35: 115.5 | K35: 145.7 | L35: 109.5 | M35: 102.9 | N35: 109.8 | O35: 112.1 | P35: 116.8 | Q35: 118.7 | R35: 113.6 | S35: 115.8 | T35: 114 | U35: 115.5 | V35: NA | W35: 110.7 | X35: 112.8 | Y35: 112.1 | Z35: 110.1 | AA35: 109.9 | AB35: 109.2 | AC35: 111.6 | AD35: 108.1 | AE35: 110.1 | AF35: 115.5 | AG35: 1509 | AH35: 113.6 | AI35: 229.8 | AJ35: 553.8 | AK35: 110.1 | AL35: 109.9 | AM35: 109.2 | AN35: 111.6
A36: Urban | B36: 2013 | C36: December | D36: 2013 December | E36: 120.5 | F36: 118.1 | G36: 128.5 | H36: 112.8 | I36: 103.4 | J36: 110.7 | K36: 144.8 | L36: 107.1 | M36: 98.6 | N36: 111.9 | O36: 112.1 | P36: 118.1 | Q36: 117.8 | R36: 115 | S36: 114.2 | T36: 110.9 | U36: 113.7 | V36: 110.7 | W36: 110.7 | X36: 110.4 | Y36: 111.3 | Z36: 109 | AA36: 109.7 | AB36: 108.9 | AC36: 111.4 | AD36: 107.7 | AE36: 109.8 | AF36: 113.3 | AG36: 1504.4 | AH36: 115 | AI36: 225.1 | AJ36: 549.9 | AK36: 109 | AL36: 109.7 | AM36: 108.9 | AN36: 111.4
A37: Rural+Urban | B37: 2013 | C37: December | D37: 2013 December | E37: 119.1 | F37: 116.7 | G37: 123.5 | H37: 113.4 | I37: 107.3 | J37: 113.3 | K37: 145.4 | L37: 108.7 | M37: 101.5 | N37: 110.5 | O37: 112.1 | P37: 117.4 | Q37: 118.4 | R37: 114 | S37: 115.2 | T37: 112.7 | U37: 114.8 | V37: 110.7 | W37: 110.7 | X37: 111.9 | Y37: 111.7 | Z37: 109.7 | AA37: 109.8 | AB37: 109 | AC37: 111.5 | AD37: 107.9 | AE37: 110 | AF37: 114.5 | AG37: 1507.3 | AH37: 114 | AI37: 227.9 | AJ37: 552.2 | AK37: 109.7 | AL37: 109.8 | AM37: 109 | AN37: 111.5
A38: Rural | B38: 2014 | C38: January | D38: 2014 January | E38: 118.9 | F38: 117.1 | G38: 120.5 | H38: 114.4 | I38: 109 | J38: 115.5 | K38: 123.9 | L38: 109.6 | M38: 101.8 | N38: 110.2 | O38: 112.4 | P38: 117.3 | Q38: 116 | R38: 114 | S38: 116.5 | T38: 114.5 | U38: 116.2 | V38: NA | W38: 111.6 | X38: 113 | Y38: 112.6 | Z38: 110.6 | AA38: 110.5 | AB38: 109.6 | AC38: 111.8 | AD38: 108.3 | AE38: 110.6 | AF38: 114.2 | AG38: 1486.6 | AH38: 114 | AI38: 231 | AJ38: 556.1 | AK38: 110.6 | AL38: 110.5 | AM38: 109.6 | AN38: 111.8
A39: Urban | B39: 2014 | C39: January | D39: 2014 January | E39: 121.2 | F39: 122 | G39: 129.9 | H39: 113.6 | I39: 102.9 | J39: 112.1 | K39: 118.9 | L39: 107.5 | M39: 96.9 | N39: 112.7 | O39: 112.1 | P39: 119 | Q39: 115.5 | R39: 115.7 | S39: 114.8 | T39: 111.3 | U39: 114.3 | V39: 111.6 | W39: 111.6 | X39: 111 | Y39: 111.9 | Z39: 109.7 | AA39: 110.8 | AB39: 109.8 | AC39: 111.5 | AD39: 108 | AE39: 110.5 | AF39: 112.9 | AG39: 1484.3 | AH39: 115.7 | AI39: 226.1 | AJ39: 553 | AK39: 109.7 | AL39: 110.8 | AM39: 109.8 | AN39: 111.5
A40: Rural+Urban | B40: 2014 | C40: January | D40: 2014 January | E40: 119.6 | F40: 118.8 | G40: 124.1 | H40: 114.1 | I40: 106.8 | J40: 113.9 | K40: 122.2 | L40: 108.9 | M40: 100.2 | N40: 111 | O40: 112.3 | P40: 118.1 | Q40: 115.8 | R40: 114.5 | S40: 115.8 | T40: 113.2 | U40: 115.4 | V40: 111.6 | W40: 111.6 | X40: 112.2 | Y40: 112.3 | Z40: 110.3 | AA40: 110.7 | AB40: 109.7 | AC40: 111.6 | AD40: 108.2 | AE40: 110.6 | AF40: 113.6 | AG40: 1485.8 | AH40: 114.5 | AI40: 229 | AJ40: 554.9 | AK40: 110.3 | AL40: 110.7 | AM40: 109.7 | AN40: 111.6
...

Sheet Problem statement

Sheet ana-1
E4: Year | F4: 2023
E5: Month | F5: May
E7: Row Labels | F7: Sum of Food category | G7: Sum of Education cat | H7: Sum of Recreation & amusement cat | I7: Sum of Transport category | J7: Sum of Health category | K7: Sum of Housing categpry | L7: Sum of Clothing category | M7: Sum of Tobacco category
E8: Rural | F8: 2290.7 | G8: 180.3 | H8: 173.8 | I8: 169.7 | J8: 187.8 | K8: 902.3 | L8: 379.1 | M8: 199.9
E9: Rural+Urban | F9: 2306.9 | G9: 177.1 | H9: 171.2 | I9: 164.8 | J9: 185.7 | K9: 894.5 | L9: 367 | M9: 201
E10: Urban | F10: 2335.1 | G10: 174.8 | H10: 169.2 | I10: 160.4 | J10: 182.2 | K10: 886.3 | L10: 349.4 | M10: 204.2
E11: Grand Total | F11: 6932.7 | G11: 532.2 | H11: 514.2 | I11: 494.9 | J11: 555.7 | K11: 2683.1 | L11: 1095.5 | M11: 605.1
E41: Row Labels | F41: Month | G41: Sum of Food category | H41: Sum of Education cat | I41: Sum of Recreation & amusement cat | J41: Sum of Transport category | K41: Sum of Health category | L41: Sum of Housing categpry | M41: Sum of Clothing category | N41: Sum of Tobacco category | O41: Total | P41: % of Food category | Q41: % of Education cat | R41: % of Recreation & amusement cat | S41: % of Transport category | T41: % of Health category | U41: % of Housing categpry | V41: % of Clothing category | W41: % of Tobacco category
E42: Rural | F42: 2023 May | G42: =SUMIFS('CIP-Main data'!$AG$1:$AG$373,'CIP-Main data'!$A$1:$A$373,'ana-1'!$E42,'CIP-Main data'!$D$1:$D$373,'ana-1'!$F42) -> 2290.7 | H42: 180.3 | I42: 173.8 | J42: 169.7 | K42: 187.8 | L42: 902.3 | M42: 379.1 | N42: 199.9 | O42: =SUM(G42:N42) -> 4483.6 | P42: =(G$42/$O$42) -> 0.51090641 | Q42: =(H$42/$O$42) -> 0.040213222 | R42: =(I$42/$O$42) -> 0.038763494 | S42: =(J$42/$O$42) -> 0.03784905 | T42: =(K$42/$O$42) -> 0.041885984 | U42: =(L$42/$O$42) -> 0.20124454 | V42: =(M$42/$O$42) -> 0.084552592 | W42: =(N$42/$O$42) -> 0.044584709
E43: Rural+Urban | F43: 2023 May | G43: =SUMIFS('CIP-Main data'!$AG$1:$AG$373,'CIP-Main data'!$A$1:$A$373,'ana-1'!$E43,'CIP-Main data'!$D$1:$D$373,'ana-1'!$F43) -> 2306.9 | H43: 177.1 | I43: 171.2 | J43: 164.8 | K43: 185.7 | L43: 894.5 | M43: 367 | N43: 201 | O43: =SUM(F43:N43) -> 4468.2 | P43: =(G$43/$O$43) -> 0.51629291 | Q43: =(H$43/$O$43) -> 0.039635647 | R43: =(I$43/$O$43) -> 0.038315205 | S43: =(J$43/$O$43) -> 0.036882861 | T43: =(K$43/$O$43) -> 0.04156036 | U43: =(L$43/$O$43) -> 0.20019247 | V43: =(M$43/$O$43) -> 0.082135983 | W43: =(N$43/$O$43) -> 0.044984558
E44: Urban | F44: 2023 May | G44: =SUMIFS('CIP-Main data'!$AG$1:$AG$373,'CIP-Main data'!$A$1:$A$373,'ana-1'!$E44,'CIP-Main data'!$D$1:$D$373,'ana-1'!$F44) -> 2335.1 | H44: 174.8 | I44: 169.2 | J44: 160.4 | K44: 182.2 | L44: 886.3 | M44: 349.4 | N44: 204.2 | O44: =SUM(G44:N44) -> 4461.6 | P44: =(G$44/$O$44) -> 0.52337726 | Q44: =(H$44/$O$44) -> 0.03917877 | R44: =(I$44/$O$44) -> 0.037923615 | S44: =(J$44/$O$44) -> 0.035951228 | T44: =(K$44/$O$44) -> 0.040837368 | U44: =(L$44/$O$44) -> 0.19865071 | V44: =(M$44/$O$44) -> 0.078312713 | W44: =(N$44/$O$44) -> 0.045768334

Sheet Ana-2
K15: Rural + Urban
K17: Row Labels | L17: Sum of General index | M17: Inflation
I18: Rural+Urban | K18: 2013 | L18: =SUMIFS('CIP-Main data'!$AF$1:$AF$373,'CIP-Main data'!$A$1:$A$373,'Ana-2'!$I$18,'CIP-Main data'!$B$1:$B$373,'Ana-2'!$K18) -> 1320.4
K19: 2014 | L19: 1408.2 | M19: =(L19-L18)/L18 -> 0.066495002
K20: 2015 | L20: 1477.3 | M20: =(L20-L19)/L19 -> 0.049069734
K21: 2016 | L21: 1550.4 | M21: =(L21-L20)/L20 -> 0.049482163
K22: 2017 | L22: 1602 | M22: =(L22-L21)/L21 -> 0.033281734
K23: 2018 | L23: 1665.3 | M23: =(L23-L22)/L22 -> 0.039513109
K24: 2019 | L24: 1586 | M24: =(L24-L23)/L23 -> -0.047619048
K25: 2020 | L25: 1836.2996 | M25: =(L25-L24)/L24 -> 0.15781813
K26: 2021 | L26: 1937.5 | M26: =(L26-L25)/L25 -> 0.055111073
K27: 2022 | L27: 2065.8 | M27: =(L27-L26)/L26 -> 0.066219355
K28: 2023 | L28: 888.1 | M28: =(L28-L27)/L27 -> -0.57009391
AD33: 2020
K34: Row Labels | L34: Sum of Food category | M34: YOY Inflation | N34: Tobacco category | O34: YOY Inflation | P34: Clothing category | Q34: YOY Inflation | R34: Health category | S34: YOY Inflation | T34: Transport category | U34: YOY Inflation | V34: Recreation & amusement cat | W34: YOY Inflation | X34: Education cat | Y34: YOY Inflation | Z34: Housing category | AA34: YOY Inflation | AD34: Broader Categories | AE34: YOY Inflation
K35: 2017 | L35: =SUMIFS('CIP-Main data'!$AG$1:$AG$373,'CIP-Main data'!$B$1:$B$373,'Ana-2'!$K35) -> 63105.7 | N35: =SUMIFS('CIP-Main data'!$AH$1:$AH$373,'CIP-Main data'!$B$1:$B$373,'Ana-2'!$K35) -> 5356.2 | P35: =SUMIFS('CIP-Main data'!$AI$1:$AI$373,'CIP-Main data'!$B$1:$B$373,'Ana-2'!$K35) -> 9726.3 | R35: =SUMIFS('CIP-Main data'!$AK$1:$AK$373,'CIP-Main data'!$B$1:$B$373,'Ana-2'!$K35) -> 4641.8 | T35: =SUMIFS('CIP-Main data'!$AL$1:$AL$373,'CIP-Main data'!$B$1:$B$373,'Ana-2'!$K35) -> 4227.5 | V35: =SUMIFS('CIP-Main data'!$AM$1:$AM$373,'CIP-Main data'!$B$1:$B$373,'Ana-2'!$K35) -> 4566.1 | X35: =SUMIFS('CIP-Main data'!$AN$1:$AN$373,'CIP-Main data'!$B$1:$B$373,'Ana-2'!$K35) -> 4902.7 | Z35: =SUMIFS('CIP-Main data'!$AJ$1:$AJ$373,'CIP-Main data'!$B$1:$B$373,'Ana-2'!$K35) -> 23215.6 | AD35: Food category | AE35: 0.1921605
K36: 2018 | L36: 63691.5 | M36: =(L36-L35)/L35 -> 0.0092828382 | N36: 5725.3 | O36: =(N36-N35)/N35 -> 0.068910795 | P36: 10161 | Q36: =(P36-P35)/P35 -> 0.044693254 | R36: 4932.2 | S36: =(R36-R35)/R35 -> 0.062561937 | T36: 4440.1 | U36: =(T36-T35)/T35 -> 0.050289769 | V36: 4800.8 | W36: =(V36-V35)/V35 -> 0.051400539 | X36: 5185.3 | Y36: =(X36-X35)/X35 -> 0.057641708 | Z36: 24597.5 | AA36: =(Z36-Z35)/Z35 -> 0.05952463 | AD36: Tobacco category | AE36: 0.18906342
K37: 2019 | L37: 60559.8 | M37: =(L37-L36)/L36 -> -0.049169826 | N37: 5473.7 | O37: =(N37-N36)/N36 -> -0.043945295 | P37: 9500.7 | Q37: =(P37-P36)/P36 -> -0.064983761 | R37: 4848.5 | S37: =(R37-R36)/R36 -> -0.016970115 | T37: 4151 | U37: =(T37-T36)/T36 -> -0.065111146 | V37: 4634 | W37: =(V37-V36)/V36 -> -0.034744209 | X37: 5073.5 | Y37: =(X37-X36)/X36 -> -0.021560951 | Z37: 23415.7 | AA37: =(Z37-Z36)/Z36 -> -0.048045533 | AD37: Clothing category | AE37: 0.11756195
K38: 2020 | L38: 72197.002 | M38: =(L38-L37)/L37 -> 0.1921605 | N38: 6508.5765 | O38: =(N38-N37)/N37 -> 0.18906342 | P38: 10617.621 | Q38: =(P38-P37)/P37 -> 0.11756195 | R38: 5519.0656 | S38: =(R38-R37)/R37 -> 0.13830373 | T38: 4918.459 | U38: =(T38-T37)/T37 -> 0.18488533 | V38: 5283.9948 | W38: =(V38-V37)/V37 -> 0.14026648 | X38: 5673.8444 | Y38: =(X38-X37)/X37 -> 0.11832943 | Z38: 26811.767 | AA38: =(Z38-Z37)/Z37 -> 0.14503377 | AD38: Health category | AE38: 0.13830373
K39: 2021 | L39: 76441.9 | M39: =(L39-L38)/L38 -> 0.058796049 | N39: 6900.4 | O39: =(N39-N38)/N38 -> 0.060201111 | P39: 11272.6 | Q39: =(P39-P38)/P38 -> 0.061687939 | R39: 5944.8 | S39: =(R39-R38)/R38 -> 0.07713885 | T39: 5425.2 | U39: =(T39-T38)/T38 -> 0.10302841 | V39: 5614 | W39: =(V39-V38)/V38 -> 0.062453723 | X39: 5851.3 | Y39: =(X39-X38)/X38 -> 0.031276085 | Z39: 28488.6 | AA39: =(Z39-Z38)/Z38 -> 0.062540923 | AD39: Transport category | AE39: 0.18488533
K40: 2022 | L40: 80879 | M40: =(L40-L39)/L39 -> 0.058045391 | N40: 7039.9 | O40: =(N40-N39)/N39 -> 0.020216219 | P40: 12432.3 | Q40: =(P40-P39)/P39 -> 0.10287777 | R40: 6312.7 | S40: =(R40-R39)/R39 -> 0.061886018 | T40: 5804.7 | U40: =(T40-T39)/T39 -> 0.069951338 | V40: 5972.4 | W40: =(V40-V39)/V39 -> 0.063840399 | X40: 6127.1 | Y40: =(X40-X39)/X39 -> 0.047134825 | Z40: 30485.5 | AA40: =(Z40-Z39)/Z39 -> 0.070094705 | AD40: Recreation & amusement cat | AE40: 0.14026648
K41: 2023 | L41: 34396.7 | M41: =(L41-L40)/L40 -> -0.57471408 | N41: 3006.5 | O41: =(N41-N40)/N40 -> -0.57293427 | P41: 5448.3 | Q41: =(P41-P40)/P40 -> -0.56176251 | R41: 2758.5 | S41: =(R41-R40)/R40 -> -0.56302375 | T41: 2466.2 | U41: =(T41-T40)/T40 -> -0.57513739 | V41: 2559 | W41: =(V41-V40)/V40 -> -0.57152903 | X41: 2638.1 | Y41: =(X41-X40)/X40 -> -0.56943742 | Z41: 13295.7 | AA41: =(Z41-Z40)/Z40 -> -0.56386807 | AD41: Education cat | AE41: 0.11832943
L42: =SUM(L35:L41) -> 451271.6 | M42: =SUM(M36:M41) -> -0.30559913 | N42: =SUM(N35:N41) -> 40010.576 | O42: =SUM(O36:O41) -> -0.27848802 | P42: =SUM(P35:P41) -> 69158.821 | Q42: =SUM(Q36:Q41) -> -0.29992535 | R42: =SUM(R35:R41) -> 34957.566 | S42: =SUM(S36:S41) -> -0.24010333 | T42: =SUM(T35:T41) -> 31433.159 | U42: =SUM(U36:U41) -> -0.23209369 | V42: =SUM(V35:V41) -> 33430.295 | W42: =SUM(W36:W41) -> -0.28831211 | X42: =SUM(X35:X41) -> 35451.844 | Y42: =SUM(Y36:Y41) -> -0.33661632 | Z42: =SUM(Z35:Z41) -> 170310.37 | AA42: =SUM(AA36:AA41) -> -0.27471957 | AD42: Housing category | AE42: 0.14503377

Sheet Ana-3
M3: Cereals and products | N3: MoM Inflation | O3: Sum of Food and beverages | P3: MoM Inflation | Q3: Sum of Prepared meals, snacks, sweets etc. | R3: MoM Inflation | S3: Sum of Non-alcoholic beverages | T3: MoM Inflation | U3: Sum of Spices | V3: MoM Inflation | W3: Sum of Sugar and Confectionery | X3: MoM Inflation | Y3: Sum of Pulses and products | Z3: MoM Inflation | AA3: Sum of Vegetables | AB3: MoM Inflation | AC3: Sum of Fruits | AD3: MoM Inflation | AE3: Sum of Oils and fats | AF3: MoM Inflation | AG3: Sum of Milk and products | AH3: MoM Inflation | AI3: Sum of Egg | AJ3: MoM Inflation | AK3: Sum of Meat and fish | AL3: MoM Inflation | AR3: June 2022-May 2023
L4: 2022 June | M4: =SUMIFS('CIP-Main data'!$E$1:$E$373,'CIP-Main data'!$D$1:$D$373,'Ana-3'!$L4) -> 466.3 | O4: =SUMIFS('CIP-Main data'!$Q$1:$Q$373,'CIP-Main data'!$D$1:$D$373,'Ana-3'!$L4) -> 526.6 | Q4: =SUMIFS('CIP-Main data'!$P$1:$P$373,'CIP-Main data'!$D$1:$D$373,'Ana-3'!$L4) -> 552.1 | S4: =SUMIFS('CIP-Main data'!$O$1:$O$373,'CIP-Main data'!$D$1:$D$373,'Ana-3'!$L4) -> 501.2 | U4: =SUMIFS('CIP-Main data'!$N$1:$N$373,'CIP-Main data'!$D$1:$D$373,'Ana-3'!$L4) -> 559.5 | W4: =SUMIFS('CIP-Main data'!$M$1:$M$373,'CIP-Main data'!$D$1:$D$373,'Ana-3'!$L4) -> 360.4 | Y4: =SUMIFS('CIP-Main data'!$L$1:$L$373,'CIP-Main data'!$D$1:$D$373,'Ana-3'!$L4) -> 492.5 | AA4: =SUMIFS('CIP-Main data'!$K$1:$K$373,'CIP-Main data'!$D$1:$D$373,'Ana-3'!$L4) -> 561.1 | AC4: =SUMIFS('CIP-Main data'!$J$1:$J$373,'CIP-Main data'!$D$1:$D$373,'Ana-3'!$L4) -> 509.6 | AE4: =SUMIFS('CIP-Main data'!$I$1:$I$373,'CIP-Main data'!$D$1:$D$373,'Ana-3'!$L4) -> 597.6 | AG4: =SUMIFS('CIP-Main data'!$H$1:$H$373,'CIP-Main data'!$D$1:$D$373,'Ana-3'!$L4) -> 497.6 | AI4: =SUMIFS('CIP-Main data'!$G$1:$G$373,'CIP-Main data'!$D$1:$D$373,'Ana-3'!$L4) -> 513.2 | AK4: =SUMIFS('CIP-Main data'!$F$1:$F$373,'CIP-Main data'!$D$1:$D$373,'Ana-3'!$L4) -> 660 | AR4: Cereals and products | AS4: 0.11309709
D5: Month with year | E5: Food category | F5: Inflation | L5: 2022 July | M5: 471 | N5: =(M5-M4)/M4 -> 0.010079348 | O5: 526.9 | P5: =(O5-O4)/O4 -> 0.00056969237 | Q5: 556 | R5: =(Q5-Q4)/Q4 -> 0.0070639377 | S5: 502.7 | T5: =(S5-S4)/S4 -> 0.0029928172 | U5: 568.1 | V5: =(U5-U4)/U4 -> 0.015370867 | W5: 360.7 | X5: =(W5-W4)/W4 -> 0.00083240844 | Y5: 492.7 | Z5: =(Y5-Y4)/Y4 -> 0.00040609137 | AA5: 559.2 | AB5: =(AA5-AA4)/AA4 -> -0.0033862057 | AC5: 523.3 | AD5: =(AC5-AC4)/AC4 -> 0.02688383 | AE5: 582.8 | AF5: =(AE5-AE4)/AE4 -> -0.02476573 | AG5: 500 | AH5: =(AG5-AG4)/AG4 -> 0.0048231511 | AI5: 526.1 | AJ5: =(AI5-AI4)/AI4 -> 0.025136399 | AK5: 640.9 | AL5: =(AK5-AK4)/AK4 -> -0.028939394 | AR5: Meat and fish | AS5: -0.021180873
D6: 2022 June | E6: =SUMIFS('CIP-Main data'!$AG$1:$AG$373,'CIP-Main data'!$D$1:$D$373,'Ana-3'!$D6) -> 6797.7 | L6: 2022 August | M6: 481.9 | N6: 0.023142251 | O6: 530.6 | P6: 0.0070222054 | Q6: 559.2 | R6: 0.0057553957 | S6: 504.1 | T6: 0.0027849612 | U6: 578.9 | V6: 0.019010738 | W6: 363.3 | X6: 0.0072082063 | Y6: 501.6 | Z6: 0.01806373 | AA6: 572.9 | AB6: 0.024499285 | AC6: 519.2 | AD6: -0.0078348939 | AE6: 573 | AF6: -0.016815374 | AG6: 504.4 | AH6: 0.0088 | AI6: 508.1 | AJ6: -0.034214028 | AK6: 621.5 | AL6: -0.030269933 | AR6: Egg | AS6: 0.025085116
D7: 2022 July | E7: 6810.4 | F7: =(E7-E6)/E6 -> 0.001868279 | L7: 2022 September | M7: 491.3 | N7: 0.019506122 | O7: 535.1 | P7: 0.0084809649 | Q7: 562.6 | R7: 0.0060801144 | S7: 505.9 | T7: 0.0035707201 | U7: 590 | V7: 0.019174296 | W7: 365.5 | X7: 0.0060556014 | Y7: 507.3 | Z7: 0.011363636 | AA7: 589.5 | AB7: 0.028975388 | AC7: 497.3 | AD7: -0.042180277 | AE7: 562.1 | AF7: -0.019022688 | AG7: 509.3 | AH7: 0.0097145123 | AI7: 509.6 | AJ7: 0.0029521748 | AK7: 629.6 | AL7: 0.013032985 | AR7: Milk and products | AS7: 0.079344722
D8: 2022 August | E8: 6818.7 | F8: =(E8-E7)/E7 -> 0.0012187243 | L8: 2022 October | M8: 496.3 | N8: 0.010177081 | O8: 540.3 | P8: 0.0097178098 | Q8: 565.4 | R8: 0.004976893 | S8: 507.3 | T8: 0.0027673453 | U8: 597.9 | V8: 0.013389831 | W8: 366.4 | X8: 0.0024623803 | Y8: 509.4 | Z8: 0.0041395624 | AA8: 613.1 | AB8: 0.040033927 | AC8: 491.7 | AD8: -0.011260808 | AE8: 555.8 | AF8: -0.01120797 | AG8: 512.8 | AH8: 0.0068721775 | AI8: 513.1 | AJ8: 0.0068681319 | AK8: 634.6 | AL8: 0.0079415502 | AR8: Oils and fats | AS8: -0.16068758
D9: 2022 September | E9: 6855.1 | F9: =(E9-E8)/E8 -> 0.005338261 | L9: 2022 November | M9: 502.7 | N9: 0.012895426 | O9: 536.2 | P9: -0.0075883768 | Q9: 568.8 | R9: 0.0060134418 | S9: 508.9 | T9: 0.0031539523 | U9: 606.4 | V9: 0.014216424 | W9: 367 | X9: 0.0016375546 | Y9: 511.7 | Z9: 0.0045151158 | AA9: 560.2 | AB9: -0.086282825 | AC9: 482.4 | AD9: -0.018913972 | AE9: 562.9 | AF9: 0.012774379 | AG9: 516.9 | AH9: 0.0079953198 | AI9: 544.8 | AJ9: 0.061781329 | AK9: 630 | AL9: -0.0072486606 | AR9: Fruits | AS9: 0.01956658
D10: 2022 October | E10: 6904.1 | F10: =(E10-E9)/E9 -> 0.0071479628 | L10: 2022 December | M10: 508.2 | N10: 0.010940919 | O10: 528.9 | P10: -0.013614323 | Q10: 571.3 | R10: 0.004395218 | S10: 510.6 | T10: 0.0033405384 | U10: 613.2 | V10: 0.01121372 | W10: 366.1 | X10: -0.0024523161 | Y10: 512.6 | Z10: 0.0017588431 | AA10: 488.8 | AB10: -0.12745448 | AC10: 474.2 | AD10: -0.016998342 | AE10: 561.5 | AF10: -0.0024871203 | AG10: 520.9 | AH10: 0.0077384407 | AI10: 571.2 | AJ10: 0.04845815 | AK10: 628.8 | AL10: -0.0019047619 | AR10: Vegetables | AS10: -0.11025198
D11: 2022 November | E11: 6898.9 | F11: =(E11-E10)/E10 -> -0.00075317565 | L11: 2023 January | M11: 521.1 | N11: 0.025383707 | O11: 531.2 | P11: 0.0043486481 | Q11: 574 | R11: 0.0047260634 | S11: 512 | T11: 0.0027418723 | U11: 623.2 | V11: 0.016307893 | W11: 364.1 | X11: -0.0054629883 | Y11: 512.8 | Z11: 0.00039016777 | AA11: 472.1 | AB11: -0.034165303 | AC11: 475.1 | AD11: 0.0018979334 | AE11: 557.8 | AF11: -0.0065894924 | AG11: 524.1 | AH11: 0.0061432137 | AI11: 584.4 | AJ11: 0.023109244 | AK11: 634.2 | AL11: 0.0085877863 | AR11: Pulses and products | AS11: 0.068883627
D12: 2022 December | E12: 6856.3 | F12: =(E12-E11)/E11 -> -0.0061748974 | G12: Lowest | L12: 2023 February | M12: 523.3 | N12: 0.0042218384 | O12: 532.5 | P12: 0.0024472892 | Q12: 579.5 | R12: 0.0095818815 | S12: 514.8 | T12: 0.00546875 | U12: 626.6 | V12: 0.0054557125 | W12: 361 | X12: -0.0085141445 | Y12: 513.6 | Z12: 0.0015600624 | AA12: 469.4 | AB12: -0.0057191273 | AC12: 508.8 | AD12: 0.070932435 | AE12: 534.9 | AF12: -0.041054141 | AG12: 532.2 | AH12: 0.015455066 | AI12: 526.3 | AJ12: -0.099418207 | AK12: 625.1 | AL12: -0.014348786 | AR12: Sugar and Confectionery | AS12: 0.02325793
D13: 2023 January | E13: 6886.1 | F13: =(E13-E12)/E12 -> 0.0043463676 | L13: 2023 March | M13: 523.4 | N13: 0.00019109497 | O13: 532.6 | P13: 0.00018779343 | Q13: 579.5 | R13: 0 | S13: 514.8 | T13: 0 | U13: 626.6 | V13: 0 | W13: 361 | X13: 0 | Y13: 513.8 | Z13: 0.0003894081 | AA13: 469.6 | AB13: 0.00042607584 | AC13: 508.8 | AD13: 0 | AE13: 534.7 | AF13: -0.00037390166 | AG13: 532.2 | AH13: 0 | AI13: 526.3 | AJ13: 0 | AK13: 625.1 | AL13: 0 | AR13: Spices | AS13: 0.1525662
D14: 2023 February | E14: 6848 | F14: =(E14-E13)/E13 -> -0.0055328851 | L14: 2023 April | M14: 521.9 | N14: -0.002865877 | O14: 535.5 | P14: 0.0054449869 | Q14: 581 | R14: 0.0025884383 | S14: 516.6 | T14: 0.0034965035 | U14: 636.2 | V14: 0.015320779 | W14: 364.8 | X14: 0.010526316 | Y14: 520.9 | Z14: 0.013818606 | AA14: 478.1 | AB14: 0.018100511 | AC14: 529.2 | AD14: 0.04009434 | AE14: 522.1 | AF14: -0.023564616 | AG14: 535.4 | AH14: 0.0060127772 | AI14: 509.9 | AJ14: -0.031160935 | AK14: 629.9 | AL14: 0.0076787714 | AR14: Non-alcoholic beverages | AS14: 0.033027487
D15: 2023 March | E15: 6848.4 | F15: =(E15-E14)/E14 -> 5.8411215e-05 | L15: 2023 May | M15: 521.6 | N15: -0.00057482276 | O15: 539 | P15: 0.0065359477 | Q15: 583 | R15: 0.0034423408 | S15: 518 | T15: 0.0027100271 | U15: 650.9 | V15: 0.023105942 | W15: 368.8 | X15: 0.010964912 | Y15: 527.4 | Z15: 0.012478403 | AA15: 494.7 | AB15: 0.03472077 | AC15: 517 | AD15: -0.023053666 | AE15: 507.7 | AF15: -0.027580923 | AG15: 538.5 | AH15: 0.0057900635 | AI15: 520.9 | AJ15: 0.021572857 | AK15: 645.2 | AL15: 0.02428957 | AR15: Prepared meals, snacks, sweets etc. | AS15: 0.054623725
D16: 2023 April | E16: 6881.5 | F16: =(E16-E15)/E15 -> 0.0048332457 | L16: Total | M16: =SUM(M4:M15) -> 6029 | N16: =SUM(N5:N15) -> 0.11309709 | O16: =SUM(O4:O15) -> 6395.4 | P16: =SUM(P5:P15) -> 0.023552638 | Q16: =SUM(Q4:Q15) -> 6832.4 | R16: =SUM(R5:R15) -> 0.054623725 | S16: =SUM(S4:S15) -> 6116.9 | T16: =SUM(T5:T15) -> 0.033027487 | U16: =SUM(U4:U14) -> 6626.6 | V16: =SUM(V5:V15) -> 0.1525662 | W16: =SUM(W4:W15) -> 4369.1 | X16: =SUM(X5:X15) -> 0.02325793 | Y16: =SUM(Y4:Y15) -> 6116.3 | Z16: =SUM(Z5:Z15) -> 0.068883627 | AA16: =SUM(AA4:AA15) -> 6328.7 | AB16: =SUM(AB5:AB15) -> -0.11025198 | AC16: =SUM(AC4:AC15) -> 6036.6 | AD16: =SUM(AD5:AD15) -> 0.01956658 | AE16: =SUM(AE4:AE15) -> 6652.9 | AF16: =SUM(AF5:AF15) -> -0.16068758 | AG16: =SUM(AG4:AG15) -> 6224.3 | AH16: =SUM(AH5:AH15) -> 0.079344722 | AI16: =SUM(AI4:AI15) -> 6353.9 | AJ16: =SUM(AJ5:AJ15) -> 0.025085116 | AK16: =SUM(AK4:AK15) -> 7604.9 | AL16: =SUM(AL5:AL15) -> -0.021180873 | AR16: Food and beverages | AS16: 0.023552638
D17: 2023 May | E17: 6932.7 | F17: =(E17-E16)/E16 -> 0.0074402383 | G17: Highest
L40: Row Labels | M40: Sum of Cereals and products | N40: Sum of Food and beverages | O40: Sum of Prepared meals, snacks, sweets etc. | P40: Sum of Non-alcoholic beverages | Q40: Sum of Spices | R40: Sum of Sugar and Confectionery | S40: Sum of Pulses and products | T40: Sum of Vegetables | U40: Sum of Fruits | V40: Sum of Oils and fats | W40: Sum of Milk and products | X40: Sum of Egg | Y40: Sum of Meat and fish
L41: 2022 August | M41: 481.9 | N41: 530.6 | O41: 559.2 | P41: 504.1 | Q41: 578.9 | R41: 363.3 | S41: 501.6 | T41: 572.9 | U41: 519.2 | V41: 573 | W41: 504.4 | X41: 508.1 | Y41: 621.5
L42: 2022 December | M42: 508.2 | N42: 528.9 | O42: 571.3 | P42: 510.6 | Q42: 613.2 | R42: 366.1 | S42: 512.6 | T42: 488.8 | U42: 474.2 | V42: 561.5 | W42: 520.9 | X42: 571.2 | Y42: 628.8
L43: 2022 July | M43: 471 | N43: 526.9 | O43: 556 | P43: 502.7 | Q43: 568.1 | R43: 360.7 | S43: 492.7 | T43: 559.2 | U43: 523.3 | V43: 582.8 | W43: 500 | X43: 526.1 | Y43: 640.9
L44: 2022 June | M44: 466.3 | N44: 526.6 | O44: 552.1 | P44: 501.2 | Q44: 559.5 | R44: 360.4 | S44: 492.5 | T44: 561.1 | U44: 509.6 | V44: 597.6 | W44: 497.6 | X44: 513.2 | Y44: 660
L45: 2022 May | M45: 463.7 | N45: 521.6 | O45: 547.8 | P45: 498.8 | Q45: 552.9 | R45: 359.8 | S45: 493.8 | T45: 538.5 | U45: 513.5 | V45: 601.8 | W45: 494.9 | X45: 487.9 | Y45: 652.9
L46: 2022 November | M46: 502.7 | N46: 536.2 | O46: 568.8 | P46: 508.9 | Q46: 606.4 | R46: 367 | S46: 511.7 | T46: 560.2 | U46: 482.4 | V46: 562.9 | W46: 516.9 | X46: 544.8 | Y46: 630
L47: 2022 October | M47: 496.3 | N47: 540.3 | O47: 565.4 | P47: 507.3 | Q47: 597.9 | R47: 366.4 | S47: 509.4 | T47: 613.1 | U47: 491.7 | V47: 555.8 | W47: 512.8 | X47: 513.1 | Y47: 634.6
L48: 2022 September | M48: 491.3 | N48: 535.1 | O48: 562.6 | P48: 505.9 | Q48: 590 | R48: 365.5 | S48: 507.3 | T48: 589.5 | U48: 497.3 | V48: 562.1 | W48: 509.3 | X48: 509.6 | Y48: 629.6
L49: 2023 April | M49: 521.9 | N49: 535.5 | O49: 581 | P49: 516.6 | Q49: 636.2 | R49: 364.8 | S49: 520.9 | T49: 478.1 | U49: 529.2 | V49: 522.1 | W49: 535.4 | X49: 509.9 | Y49: 629.9
L50: 2023 February | M50: 523.3 | N50: 532.5 | O50: 579.5 | P50: 514.8 | Q50: 626.6 | R50: 361 | S50: 513.6 | T50: 469.4 | U50: 508.8 | V50: 534.9 | W50: 532.2 | X50: 526.3 | Y50: 625.1
L51: 2023 January | M51: 521.1 | N51: 531.2 | O51: 574 | P51: 512 | Q51: 623.2 | R51: 364.1 | S51: 512.8 | T51: 472.1 | U51: 475.1 | V51: 557.8 | W51: 524.1 | X51: 584.4 | Y51: 634.2
L52: 2023 March | M52: 523.4 | N52: 532.6 | O52: 579.5 | P52: 514.8 | Q52: 626.6 | R52: 361 | S52: 513.8 | T52: 469.6 | U52: 508.8 | V52: 534.7 | W52: 532.2 | X52: 526.3 | Y52: 625.1
... L54: Grand Total | M54: 6492.7 | N54: 6917 | O54: 7380.2 | P54: 6615.7 | Q54: 7830.4 | R54: 4728.9 | S54: 6610.1 | T54: 6867.2 | U54: 6550.1 | V54: 7254.7 | W54: 6719.2 | X54: 6841.8 | Y54: 8257.8
B133: =CONCATENATE($B133," ",$C133) -> 2015 December
B134: =CONCATENATE($B134," ",$C134) -> 2015 December
B135: =CONCATENATE($B135," ",$C135) -> 2015 December
B136: =CONCATENATE($B136," ",$C136) -> 2016 January
B137: =CONCATENATE($B137," ",$C137) -> 2016 January
B138: =CONCATENATE($B138," ",$C138) -> 2016 January
B139: =CONCATENATE($B139," ",$C139) -> 2016 February
B140: =CONCATENATE($B140," ",$C140) -> 2016 February
B141: =CONCATENATE($B141," ",$C141) -> 2016 February
B142: =CONCATENATE($B142," ",$C142) -> 2016 March
B143: =CONCATENATE($B143," ",$C143) -> 2016 March
...

Sheet Ana-4
F4: MOM | G4: Total of Food category | H4: Inflation | W4: MOM | X4: Sum of Health category | Y4: Inflation | AM4: MOM | AN4: Sum of R&A category | AO4: Inflation | BD4: MOM | BE4: Sum of Education category | BF4: Inflation
F5: 2019 March | G5: 5292.5 | W5: 2019 March | X5: 435.8 | AM5: 2019 March | AN5: 414.5 | BD5: 2019 March | BE5: 452.5
F6: 2019 May | G6: =SUMIFS('CIP-Main data'!$AG$1:$AG$373,'CIP-Main data'!$D$1:$D$373,'Ana-4'!$F6) -> 5385.5 | H6: =(G6-G5)/G5 -> 0.017572036 | W6: 2019 May | X6: =SUMIFS('CIP-Main data'!$AK$1:$AK$373,'CIP-Main data'!$D$1:$D$373,'Ana-4'!$W6) -> 438 | Y6: =(X6-X5)/X5 -> 0.0050481872 | AM6: 2019 May | AN6: =SUMIFS('CIP-Main data'!$AM$1:$AM$373,'CIP-Main data'!$D$1:$D$373,'Ana-4'!$AM6) -> 419.1 | AO6: =(AN6-AN5)/AN5 -> 0.011097708 | BD6: 2019 May | BE6: =SUMIFS('CIP-Main data'!$AN$1:$AN$373,'CIP-Main data'!$D$1:$D$373,'Ana-4'!$BD6) -> 456.3 | BF6: =(BE6-BE5)/BE5 -> 0.0083977901
F7: 2019 June | G7: =SUMIFS('CIP-Main data'!$AG$1:$AG$373,'CIP-Main data'!$D$1:$D$373,'Ana-4'!$F7) -> 5451.6 | H7: =(G7-G6)/G6 -> 0.012273698 | W7: 2019 June | X7: =SUMIFS('CIP-Main data'!$AK$1:$AK$373,'CIP-Main data'!$D$1:$D$373,'Ana-4'!$W7) -> 439.4 | Y7: =(X7-X6)/X6 -> 0.003196347 | AM7: 2019 June | AN7: =SUMIFS('CIP-Main data'!$AM$1:$AM$373,'CIP-Main data'!$D$1:$D$373,'Ana-4'!$AM7) -> 420.3 | AO7: =(AN7-AN6)/AN6 -> 0.0028632785 | BD7: 2019 June | BE7: =SUMIFS('CIP-Main data'!$AN$1:$AN$373,'CIP-Main data'!$D$1:$D$373,'Ana-4'!$BD7) -> 459.1 | BF7: =(BE7-BE6)/BE6 -> 0.0061363138
F8: 2019 July | G8: =SUMIFS('CIP-Main data'!$AG$1:$AG$373,'CIP-Main data'!$D$1:$D$373,'Ana-4'!$F8) -> 5521.8 | H8: =(G8-G7)/G7 -> 0.012876954 | W8: 2019 July | X8: =SUMIFS('CIP-Main data'!$AK$1:$AK$373,'CIP-Main data'!$D$1:$D$373,'Ana-4'!$W8) -> 440.9 | Y8: =(X8-X7)/X7 -> 0.003413746 | AM8: 2019 July | AN8: =SUMIFS('CIP-Main data'!$AM$1:$AM$373,'CIP-Main data'!$D$1:$D$373,'Ana-4'!$AM8) -> 423 | AO8: =(AN8-AN7)/AN7 -> 0.0064239829 | BD8: 2019 July | BE8: =SUMIFS('CIP-Main data'!$AN$1:$AN$373,'CIP-Main data'!$D$1:$D$373,'Ana-4'!$BD8) -> 463.5 | BF8: =(BE8-BE7)/BE7 -> 0.0095839686
F9: 2019 August | G9: =SUMIFS('CIP-Main data'!$AG$1:$AG$373,'CIP-Main data'!$D$1:$D$373,'Ana-4'!$F9) -> 5550.1 | H9: =(G9-G8)/G8 -> 0.0051251404 | W9: 2019 August | X9: =SUMIFS('CIP-Main data'!$AK$1:$AK$373,'CIP-Main data'!$D$1:$D$373,'Ana-4'!$W9) -> 442.7 | Y9: =(X9-X8)/X8 -> 0.0040825584 | AM9: 2019 August | AN9: =SUMIFS('CIP-Main data'!$AM$1:$AM$373,'CIP-Main data'!$D$1:$D$373,'Ana-4'!$AM9) -> 424.3 | AO9: =(AN9-AN8)/AN8 -> 0.0030732861 | BD9: 2019 August | BE9: =SUMIFS('CIP-Main data'!$AN$1:$AN$373,'CIP-Main data'!$D$1:$D$373,'Ana-4'!$BD9) -> 466.1 | BF9: =(BE9-BE8)/BE8 -> 0.005609493
F10: 2019 September | G10: =SUMIFS('CIP-Main data'!$AG$1:$AG$373,'CIP-Main data'!$D$1:$D$373,'Ana-4'!$F10) -> 5581.3 | H10: =(G10-G9)/G9 -> 0.0056215203 | W10: 2019 September | X10: =SUMIFS('CIP-Main data'!$AK$1:$AK$373,'CIP-Main data'!$D$1:$D$373,'Ana-4'!$W10) -> 444.3 | Y10: =(X10-X9)/X9 -> 0.0036141857 | AM10: 2019 September | AN10: =SUMIFS('CIP-Main data'!$AM$1:$AM$373,'CIP-Main data'!$D$1:$D$373,'Ana-4'!$AM10) -> 425.5 | AO10: =(AN10-AN9)/AN9 -> 0.0028281876 | BD10: 2019 September | BE10: =SUMIFS('CIP-Main data'!$AN$1:$AN$373,'CIP-Main data'!$D$1:$D$373,'Ana-4'!$BD10) -> 467 | BF10: =(BE10-BE9)/BE9 -> 0.0019309161
F11: 2019 October | G11: =SUMIFS('CIP-Main data'!$AG$1:$AG$373,'CIP-Main data'!$D$1:$D$373,'Ana-4'!$F11) -> 5665.1 | H11: =(G11-G10)/G10 -> 0.015014423 | W11: 2019 October | X11: =SUMIFS('CIP-Main data'!$AK$1:$AK$373,'CIP-Main data'!$D$1:$D$373,'Ana-4'!$W11) -> 445.5 | Y11: =(X11-X10)/X10 -> 0.0027008778 | AM11: 2019 October | AN11: =SUMIFS('CIP-Main data'!$AM$1:$AM$373,'CIP-Main data'!$D$1:$D$373,'Ana-4'!$AM11) -> 426.6 | AO11: =(AN11-AN10)/AN10 -> 0.0025851939 | BD11: 2019 October | BE11: =SUMIFS('CIP-Main data'!$AN$1:$AN$373,'CIP-Main data'!$D$1:$D$373,'Ana-4'!$BD11) -> 467.8 | BF11: =(BE11-BE10)/BE10 -> 0.0017130621
F12: 2019 November | G12: =SUMIFS('CIP-Main data'!$AG$1:$AG$373,'CIP-Main data'!$D$1:$D$373,'Ana-4'!$F12) -> 5739.5 | H12: =(G12-G11)/G11 -> 0.013133043 | W12: 2019 November | X12: =SUMIFS('CIP-Main data'!$AK$1:$AK$373,'CIP-Main data'!$D$1:$D$373,'Ana-4'!$W12) -> 447 | Y12: =(X12-X11)/X11 -> 0.0033670034 | AM12: 2019 November | AN12: =SUMIFS('CIP-Main data'!$AM$1:$AM$373,'CIP-Main data'!$D$1:$D$373,'Ana-4'!$AM12) -> 427.9 | AO12: =(AN12-AN11)/AN11 -> 0.0030473511 | BD12: 2019 November | BE12: =SUMIFS('CIP-Main data'!$AN$1:$AN$373,'CIP-Main data'!$D$1:$D$373,'Ana-4'!$BD12) -> 468.1 | BF12: =(BE12-BE11)/BE11 -> 0.0006412997
F13: 2019 December | G13: =SUMIFS('CIP-Main data'!$AG$1:$AG$373,'CIP-Main data'!$D$1:$D$373,'Ana-4'!$F13) -> 5843.8 | H13: =(G13-G12)/G12 -> 0.018172315 | W13: 2019 December | X13: =SUMIFS('CIP-Main data'!$AK$1:$AK$373,'CIP-Main data'!$D$1:$D$373,'Ana-4'!$W13) -> 448.4 | Y13: =(X13-X12)/X12 -> 0.0031319911 | AM13: 2019 December | AN13: =SUMIFS('CIP-Main data'!$AM$1:$AM$373,'CIP-Main data'!$D$1:$D$373,'Ana-4'!$AM13) -> 428.6 | AO13: =(AN13-AN12)/AN12 -> 0.0016358962 | BD13: 2019 December | BE13: =SUMIFS('CIP-Main data'!$AN$1:$AN$373,'CIP-Main data'!$D$1:$D$373,'Ana-4'!$BD13) -> 468.7 | BF13: =(BE13-BE12)/BE12 -> 0.0012817774
F14: 2020 January | G14: =SUMIFS('CIP-Main data'!$AG$1:$AG$373,'CIP-Main data'!$D$1:$D$373,'Ana-4'!$F14) -> 5824.4 | H14: =(G14-G13)/G13 -> -0.0033197577 | W14: 2020 January | X14: =SUMIFS('CIP-Main data'!$AK$1:$AK$373,'CIP-Main data'!$D$1:$D$373,'Ana-4'!$W14) -> 450.7 | Y14: =(X14-X13)/X13 -> 0.0051293488 | AM14: 2020 January | AN14: =SUMIFS('CIP-Main data'!$AM$1:$AM$373,'CIP-Main data'!$D$1:$D$373,'Ana-4'!$AM14) -> 430.1 | AO14: =(AN14-AN13)/AN13 -> 0.0034997667 | BD14: 2020 January | BE14: =SUMIFS('CIP-Main data'!$AN$1:$AN$373,'CIP-Main data'!$D$1:$D$373,'Ana-4'!$BD14) -> 469.9 | BF14: =(BE14-BE13)/BE13 -> 0.0025602731
F15: 2020 February | G15: =SUMIFS('CIP-Main data'!$AG$1:$AG$373,'CIP-Main data'!$D$1:$D$373,'Ana-4'!$F15) -> 5738 | H15: =(G15-G14)/G14 -> -0.014834146 | W15: 2020 February | X15: =SUMIFS('CIP-Main data'!$AK$1:$AK$373,'CIP-Main data'!$D$1:$D$373,'Ana-4'!$W15) -> 452.3 | Y15: =(X15-X14)/X14 -> 0.0035500333 | AM15: 2020 February | AN15: =SUMIFS('CIP-Main data'!$AM$1:$AM$373,'CIP-Main data'!$D$1:$D$373,'Ana-4'!$AM15) -> 431.3 | AO15: =(AN15-AN14)/AN14 -> 0.0027900488 | BD15: 2020 February | BE15: =SUMIFS('CIP-Main data'!$AN$1:$AN$373,'CIP-Main data'!$D$1:$D$373,'Ana-4'!$BD15) -> 470.3 | BF15: =(BE15-BE14)/BE14 -> 0.00085124495
F16: 2020 March | G16: =SUMIFS('CIP-Main data'!$AG$1:$AG$373,'CIP-Main data'!$D$1:$D$373,'Ana-4'!$F16) -> 5688.5 | H16: =(G16-G15)/G15 -> -0.0086266992 | W16: 2020 March | X16: =SUMIFS('CIP-Main data'!$AK$1:$AK$373,'CIP-Main data'!$D$1:$D$373,'Ana-4'!$W16) -> 454 | Y16: =(X16-X15)/X15 -> 0.0037585673 | AM16: 2020 March | AN16: =SUMIFS('CIP-Main data'!$AM$1:$AM$373,'CIP-Main data'!$D$1:$D$373,'Ana-4'!$AM16) -> 432.8 | AO16: =(AN16-AN15)/AN15 -> 0.0034778576 | BD16: 2020 March | BE16: =SUMIFS('CIP-Main data'!$AN$1:$AN$373,'CIP-Main data'!$D$1:$D$373,'Ana-4'!$BD16) -> 469.8 | BF16: =(BE16-BE15)/BE15 -> -0.0010631512
F17: 2020 April | G17: =SUMIFS('CIP-Main data'!$AG$1:$AG$373,'CIP-Main data'!$D$1:$D$373,'Ana-4'!$F17) -> 5908.9 | H17: =(G17-G16)/G16 -> 0.038744836 | W17: 2020 April | X17: =SUMIFS('CIP-Main data'!$AK$1:$AK$373,'CIP-Main data'!$D$1:$D$373,'Ana-4'!$W17) -> 449.8 | Y17: =(X17-X16)/X16 -> -0.0092511013 | AM17: 2020 April | AN17: =SUMIFS('CIP-Main data'!$AM$1:$AM$373,'CIP-Main data'!$D$1:$D$373,'Ana-4'!$AM17) -> 438.65156 | AO17: =(AN17-AN16)/AN16 -> 0.013520246 | BD17: 2020 April | BE17: =SUMIFS('CIP-Main data'!$AN$1:$AN$373,'CIP-Main data'!$D$1:$D$373,'Ana-4'!$BD17) -> 468.89531 | BF17: =(BE17-BE16)/BE16 -> -0.0019256865
... F28: 2021 March | G28: =SUMIFS('CIP-Main data'!$AG$1:$AG$373,'CIP-Main data'!$D$1:$D$373,'Ana-4'!$F28) -> 6129.6 | H28: =(G28-G27)/G27 -> -0.00016311617 | W28: 2021 March | X28: =SUMIFS('CIP-Main data'!$AK$1:$AK$373,'CIP-Main data'!$D$1:$D$373,'Ana-4'!$W28) -> 483.2 | Y28: =(X28-X27)/X27 -> 0.0026976551 | AM28: 2021 March | AN28: =SUMIFS('CIP-Main data'!$AM$1:$AM$373,'CIP-Main data'!$D$1:$D$373,'Ana-4'!$AM28) -> 459 | AO28: =(AN28-AN27)/AN27 -> 0.0070206231 | BD28: 2021 March | BE28: =SUMIFS('CIP-Main data'!$AN$1:$AN$373,'CIP-Main data'!$D$1:$D$373,'Ana-4'!$BD28) -> 481.6 | BF28: =(BE28-BE27)/BE27 -> 0.0039608088

Sheet Ana-5
H2: 2022-2023
R3: Category | S3: 2022 April | T3: 2022 May | U3: 2022 June | V3: 2022 July | W3: 2022 August | X3: 2022 September | Y3: 2022 October | Z3: 2022 November | AA3: 2022 December | AB3: 2023 January | AC3: 2023 February | AD3: 2023 March | AE3: Correlation
H4: Month with year | I4: Cruid Oil Price | J4: Fluctuation | R4: Crude Oil | S4: 21626.17 | T4: 19644.254 | U4: 19209.652 | V4: 20624.254 | W4: 17637.212 | X4: 16772.21 | Y4: 18123.447 | Z4: 19003.281 | AA4: 19617.71 | AB4: 20229.31 | AC4: 19284.873 | AD4: 20928.04
H5: 2022 April | I5: 21626.17 | R5: Cereals and products | S5: =SUMIFS('CIP-Main data'!$E$1:$E$373,'CIP-Main data'!$D$1:$D$373,'Ana-5'!S$3) -> 460.1 | T5: 463.7 | U5: 466.3 | V5: 471 | W5: 481.9 | X5: 491.3 | Y5: 496.3 | Z5: 502.7 | AA5: 508.2 | AB5: 521.1 | AC5: 523.3 | AD5: 523.4 | AE5: =CORREL($S$4:$AD$4,$S5:$AD5) -> -0.04585762
H6: 2022 May | I6: 19644.254 | J6: =(I6-I5)/I5 -> -0.091644341 | R6: Meat and fish | S6: =SUMIFS('CIP-Main data'!$F$1:$F$373,'CIP-Main data'!$D$1:$D$373,'Ana-5'!S$3) -> 637.3 | T6: 652.9 | U6: 660 | V6: 640.9 | W6: 621.5 | X6: 629.6 | Y6: 634.6 | Z6: 630 | AA6: 628.8 | AB6: 634.2 | AC6: 625.1 | AD6: 625.1 | AE6: =CORREL($S$4:$AD$4,$S6:$AD6) -> 0.20618371
H7: 2022 June | I7: 19209.652 | J7: =(I7-I6)/I6 -> -0.0221236 | R7: Egg | S7: =SUMIFS('CIP-Main data'!$G$1:$G$373,'CIP-Main data'!$D$1:$D$373,'Ana-5'!S$3) -> 493.6 | T7: 487.9 | U7: 513.2 | V7: 526.1 | W7: 508.1 | X7: 509.6 | Y7: 513.1 | Z7: 544.8 | AA7: 571.2 | AB7: 584.4 | AC7: 526.3 | AD7: 526.3 | AE7: =CORREL($S$4:$AD$4,$S7:$AD7) -> 0.14263482
H8: 2022 July | I8: 20624.254 | J8: =(I8-I7)/I7 -> 0.073640166 | R8: Milk and products | S8: =SUMIFS('CIP-Main data'!$H$1:$H$373,'CIP-Main data'!$D$1:$D$373,'Ana-5'!S$3) -> 491.9 | T8: 494.9 | U8: 497.6 | V8: 500 | W8: 504.4 | X8: 509.3 | Y8: 512.8 | Z8: 516.9 | AA8: 520.9 | AB8: 524.1 | AC8: 532.2 | AD8: 532.2 | AE8: =CORREL($S$4:$AD$4,$S8:$AD8) -> -0.01337994
H9: 2022 August | I9: 17637.212 | J9: =(I9-I8)/I8 -> -0.1448315 | R9: Oils and fats | S9: =SUMIFS('CIP-Main data'!$I$1:$I$373,'CIP-Main data'!$D$1:$D$373,'Ana-5'!S$3) -> 592.9 | T9: 601.8 | U9: 597.6 | V9: 582.8 | W9: 573 | X9: 562.1 | Y9: 555.8 | Z9: 562.9 | AA9: 561.5 | AB9: 557.8 | AC9: 534.9 | AD9: 534.7 | AE9: =CORREL($S$4:$AD$4,$S9:$AD9) -> 0.12744102
H10: 2022 September | I10: 16772.21 | J10: =(I10-I9)/I9 -> -0.049044165 | R10: Fruits | S10: =SUMIFS('CIP-Main data'!$J$1:$J$373,'CIP-Main data'!$D$1:$D$373,'Ana-5'!S$3) -> 518.2 | T10: 513.5 | U10: 509.6 | V10: 523.3 | W10: 519.2 | X10: 497.3 | Y10: 491.7 | Z10: 482.4 | AA10: 474.2 | AB10: 475.1 | AC10: 508.8 | AD10: 508.8 | AE10: =CORREL($S$4:$AD$4,$S10:$AD10) -> 0.17923746
H11: 2022 October | I11: 18123.447 | J11: =(I11-I10)/I10 -> 0.080564023 | R11: Vegetables | S11: =SUMIFS('CIP-Main data'!$K$1:$K$373,'CIP-Main data'!$D$1:$D$373,'Ana-5'!S$3) -> 510.5 | T11: 538.5 | U11: 561.1 | V11: 559.2 | W11: 572.9 | X11: 589.5 | Y11: 613.1 | Z11: 560.2 | AA11: 488.8 | AB11: 472.1 | AC11: 469.4 | AD11: 469.6 | AE11: =CORREL($S$4:$AD$4,$S11:$AD11) -> -0.65375114
H12: 2022 November | I12: 19003.281 | J12: =(I12-I11)/I11 -> 0.048546736 | R12: Pulses and products | S12: =SUMIFS('CIP-Main data'!$L$1:$L$373,'CIP-Main data'!$D$1:$D$373,'Ana-5'!S$3) -> 493.8 | T12: 493.8 | U12: 492.5 | V12: 492.7 | W12: 501.6 | X12: 507.3 | Y12: 509.4 | Z12: 511.7 | AA12: 512.6 | AB12: 512.8 | AC12: 513.6 | AD12: 513.8 | AE12: =CORREL($S$4:$AD$4,$S12:$AD12) -> -0.20165335
H13: 2022 December | I13: 19617.71 | J13: =(I13-I12)/I12 -> 0.032332771 | R13: Sugar and Confectionery | S13: =SUMIFS('CIP-Main data'!$M$1:$M$373,'CIP-Main data'!$D$1:$D$373,'Ana-5'!S$3) -> 357.7 | T13: 359.8 | U13: 360.4 | V13: 360.7 | W13: 363.3 | X13: 365.5 | Y13: 366.4 | Z13: 367 | AA13: 366.1 | AB13: 364.1 | AC13: 361 | AD13: 361 | AE13: =CORREL($S$4:$AD$4,$S13:$AD13) -> -0.62324029
H14: 2023 January | I14: 20229.31 | J14: =(I14-I13)/I13 -> 0.031175921 | R14: Spices | S14: =SUMIFS('CIP-Main data'!$N$1:$N$373,'CIP-Main data'!$D$1:$D$373,'Ana-5'!S$3) -> 542.2 | T14: 552.9 | U14: 559.5 | V14: 568.1 | W14: 578.9 | X14: 590 | Y14: 597.9 | Z14: 606.4 | AA14: 613.2 | AB14: 632.2 | AC14: 626.6 | AD14: 626.6 | AE14: =CORREL($S$4:$AD$4,$S14:$AD14) -> -0.087710992
H15: 2023 February | I15: 19284.873 | J15: =(I15-I14)/I14 -> -0.046686529 | R15: Non-alcoholic beverages | S15: =SUMIFS('CIP-Main data'!$O$1:$O$373,'CIP-Main data'!$D$1:$D$373,'Ana-5'!S$3) -> 496.1 | T15: 498.8 | U15: 501.2 | V15: 502.7 | W15: 504.1 | X15: 505.9 | Y15: 507.3 | Z15: 508.9 | AA15: 510.6 | AB15: 512 | AC15: 514.8 | AD15: 514.8 | AE15: =CORREL($S$4:$AD$4,$S15:$AD15) -> -0.082070542
H16: 2023 March | I16: 20928.04 | J16: =(I16-I15)/I15 -> 0.085204946 | R16: Prepared meals, snacks, sweets etc. | S16: =SUMIFS('CIP-Main data'!$P$1:$P$373,'CIP-Main data'!$D$1:$D$373,'Ana-5'!S$3) -> 543.1 | T16: 547.8 | U16: 552.1 | V16: 556 | W16: 559.2 | X16: 562.6 | Y16: 565.4 | Z16: 568.8 | AA16: 571.3 | AB16: 574 | AC16: 579.5 | AD16: 579.5 | AE16: =CORREL($S$4:$AD$4,$S16:$AD16) -> -0.096947374
R17: Food and beverages | S17: =SUMIFS('CIP-Main data'!$Q$1:$Q$373,'CIP-Main data'!$D$1:$D$373,'Ana-5'!S$3) -> 513.9 | T17: 521.6 | U17: 526.6 | V17: 526.9 | W17: 530.6 | X17: 535.1 | Y17: 540.3 | Z17: 536.2 | AA17: 528.9 | AB17: 531.2 | AC17: 532.5 | AD17: 532.6 | AE17: =CORREL($S$4:$AD$4,$S17:$AD17) -> -0.62204279
R18: Pan, tobacco and intoxicants | S18: =SUMIFS('CIP-Main data'!$R$1:$R$373,'CIP-Main data'!$D$1:$D$373,'Ana-5'!S$3) -> 583.8 | T18: 584.5 | U18: 585.5 | V18: 586.4 | W18: 587.4 | X18: 590.1 | Y18: 591.3 | Z18: 593 | AA18: 594.3 | AB18: 596.7 | AC18: 600.5 | AD18: 600.6 | AE18: =CORREL($S$4:$AD$4,$S18:$AD18) -> 0.047898495
H19: 2021-2022 | R19: Clothing and footwear | S19: =SUMIFS('CIP-Main data'!$U$1:$U$373,'CIP-Main data'!$D$1:$D$373,'Ana-5'!S$3) -> 516.2 | T19: 521.4 | U19: 525.8 | V19: 529.6 | W19: 533.1 | X19: 537.4 | Y19: 540.5 | Z19: 543.7 | AA19: 546.5 | AB19: 549 | AC19: 552.9 | AD19: 552.9 | AE19: =CORREL($S$4:$AD$4,$S19:$AD19) -> -0.1260257
H20: Month with year | I20: Cruid Oil Price | J20: Fluctuation | R20: Housing Updated | S20: =SUMIFS('CIP-Main data'!$W$1:$W$373,'CIP-Main data'!$D$1:$D$373,'Ana-5'!S$3) -> 501 | T20: 502.5 | U20: 500.4 | V20: 503.4 | W20: 507 | X20: 508.5 | Y20: 513.6 | Z20: 515.4 | AA20: 512.1 | AB20: 516.3 | AC20: 520.5 | AD20: 520.5 | AE20: =CORREL($S$4:$AD$4,$S20:$AD20) -> -0.045326831
H21: 2021 April | I21: 18256.492 | R21: Fuel and light | S21: =SUMIFS('CIP-Main data'!$X$1:$X$373,'CIP-Main data'!$D$1:$D$373,'Ana-5'!S$3) -> 516 | T21: 523.4 | U21: 527.6 | V21: 538.7 | W21: 536.3 | X21: 538.4 | Y21: 541.3 | Z21: 543.5 | AA21: 545.4 | AB21: 545.3 | AC21: 546.5 | AD21: 545.9 | AE21: =CORREL($S$4:$AD$4,$S21:$AD21) -> -0.23223832
H22: 2021 May | I22: 17259.238 | J22: =(I22-I21)/I21 -> -0.054624621 | R22: Household goods and services | S22: =SUMIFS('CIP-Main data'!$Y$1:$Y$373,'CIP-Main data'!$D$1:$D$373,'Ana-5'!S$3) -> 491.5 | T22: 495.2 | U22: 498.8 | V22: 501.8 | W22: 505 | X22: 508.1 | Y22: 510.8 | Z22: 513.8 | AA22: 515.8 | AB22: 518.1 | AC22: 522 | AD22: 522 | AE22: =CORREL($S$4:$AD$4,$S22:$AD22) -> -0.1054757
H23: 2021 June | I23: 15904.741 | J23: =(I23-I22)/I22 -> -0.078479568 | R23: Health | S23: =SUMIFS('CIP-Main data'!$Z$1:$Z$373,'CIP-Main data'!$D$1:$D$373,'Ana-5'!S$3) -> 520 | T23: 522.6 | U23: 524.5 | V23: 526.6 | W23: 528.8 | X23: 531.8 | Y23: 534.6 | Z23: 537.9 | AA23: 541.8 | AB23: 545.5 | AC23: 551.8 | AD23: 551.8 | AE23: =CORREL($S$4:$AD$4,$S23:$AD23) -> 0.046650607
H24: 2021 July | I24: 15021.215 | J24: =(I24-I23)/I23 -> -0.055551066 | R24: Transport and communication | S24: =SUMIFS('CIP-Main data'!$AA$1:$AA$373,'CIP-Main data'!$D$1:$D$373,'Ana-5'!S$3) -> 488.1 | T24: 489.5 | U24: 483.8 | V24: 485.3 | W24: 486.2 | X24: 487.4 | Y24: 489.1 | Z24: 489.4 | AA24: 490.6 | AB24: 491.3 | AC24: 493 | AD24: 493 | AE24: =CORREL($S$4:$AD$4,$S24:$AD24) -> 0.25503703
H25: 2021 August | I25: 17386.687 | J25: =(I25-I24)/I24 -> 0.15747536 | R25: Recreation and amusement | S25: =SUMIFS('CIP-Main data'!$AB$1:$AB$373,'CIP-Main data'!$D$1:$D$373,'Ana-5'!S$3) -> 493.8 | T25: 495.9 | U25: 497.9 | V25: 499.5 | W25: 501.3 | X25: 503.4 | Y25: 505.1 | Z25: 506 | AA25: 507.2 | AB25: 509.1 | AC25: 511.5 | AD25: 511.5 | AE25: =CORREL($S$4:$AD$4,$S25:$AD25) -> -0.10357743
H26: 2021 September | I26: 17607.535 | J26: =(I26-I25)/I25 -> 0.01270214 | R26: Education | S26: =SUMIFS('CIP-Main data'!$AC$1:$AC$373,'CIP-Main data'!$D$1:$D$373,'Ana-5'!S$3) -> 501.8 | T26: 504.9 | U26: 508.1 | V26: 515.2 | W26: 517.9 | X26: 520.2 | Y26: 521.1 | Z26: 522.1 | AA26: 523.2 | AB26: 523.9 | AC26: 526 | AD26: 526 | AE26: =CORREL($S$4:$AD$4,$S26:$AD26) -> -0.27227981
